<?xml version="1.0" encoding="UTF-8"?>
<robot name="pi_robot">
   <link name="left_back_link">
      <visual>
         <origin xyz="-0.05 0 0" rpy="0 0 0" />
         <geometry>
            <box size="0.15 0.05 0.15" />
         </geometry>
         <material name="Red1" />
      </visual>
   </link>
   <link name="right_back_link">
      <visual>
         <origin xyz="-0.05 0 0" rpy="0 0 0" />
         <geometry>
            <box size="0.15 0.05 0.15" />
         </geometry>
         <material name="Red1" />
      </visual>
   </link>
   <link name="right_front_link">
      <visual>
         <origin xyz="0.05 0 0" rpy="0 0 0" />
         <geometry>
            <box size="0.15 0.05 0.15" />
         </geometry>
         <material name="Red1" />
      </visual>
   </link>
   <link name="left_front_leg_link">
      <visual>
         <origin xyz="0 0 0" rpy="0 0 0" />
         <geometry>
            <box size="0.05 0.05 0.25" />
         </geometry>
         <material name="Red1" />
      </visual>
   </link>
   <link name="left_front_link">
      <visual>
         <origin xyz="0.05 0 0" rpy="0 0 0" />
         <geometry>
            <box size="0.15 0.05 0.15" />
         </geometry>
         <material name="Red1" />
      </visual>
   </link>
   <!-- * * * Link Definitions * * * -->
   <joint name="right_back_joint" type="revolute">
      <parent link="base_link" />
      <child link="right_back_link" />
      <origin xyz="-0.15 -0.1 0" rpy="0 0 0" />
      <axis xyz="0 0 1" />
      <limit lower="-6.8" upper="-4" effort="10" velocity="3" />
   </joint>
   <joint name="left_back_joint" type="revolute">
      <parent link="base_link" />
      <child link="left_back_link" />
      <origin xyz="-0.15 0.1 0" rpy="0 0 0" />
      <axis xyz="0 0 1" />
      <limit lower="-2" upper="0.3" effort="10" velocity="3" />
   </joint>
   <joint name="right_front_joint" type="revolute">
      <parent link="base_link" />
      <child link="right_front_link" />
      <origin xyz="0.15 -0.1 0" rpy="0 0 0" />
      <axis xyz="0 0 1" />
      <limit lower="-2" upper="0.6" effort="10" velocity="3" />
   </joint>
   <joint name="left_front_joint" type="revolute">
      <parent link="base_link" />
      <child link="left_front_link" />
      <origin xyz="0.15 0.1 0" rpy="0 0 0" />
      <axis xyz="0 0 1" />
      <limit lower="-0.6" upper="2" effort="10" velocity="3" />
   </joint>
   <joint name="left_front_leg_joint" type="revolute">
      <parent link="left_front_link" />
      <child link="left_front_leg_link" />
      <origin xyz="0.15 0 -0.05" rpy="0 0 0" />
      <axis xyz="0 1 0" />
      <limit lower="-0.6" upper="2" effort="10" velocity="3" />
   </joint>
   <link name="base_link">
      <visual>
         <origin xyz="0 0 0" rpy="0 0 0" />
         <geometry>
            <box size="0.32 0.26 0.085" />
         </geometry>
         <material name="Cyan1" />
      </visual>
   </link>
   <material name="Red1">
      <color rgba="0.9 0 0 1.0" />
   </material>
   <material name="Cyan1">
      <color rgba="0 0.9 0.9 1.0" />
   </material>
   <material name="Black1">
      <color rgba="0.2 0.2 0.2 1.0" />
   </material>
   <material name="Green1">
      <color rgba="0 1 0 1.0" />
   </material>
   <material name="Blue1">
      <color rgba="0 0 0.9 1.0" />
   </material>
   <material name="Grey1">
      <color rgba="0.9 0.9 0.9 1.0" />
   </material>
</robot>