<robot name="pi_robot">
	<!-- * * * Link Definitions * * * -->

  	<link name="left_front_link">
		<visual>
		    <origin xyz="0.3 0 0" rpy="0 0 0"/>
			<geometry>
				<box size="0.1 0.1 0.085"/>
			</geometry>
			<material name="Red1">
	       		<color rgba="0 0.9 0.9 1.0"/>
	     	</material>
		</visual>	
	</link>

	<joint name="left_front_joint" type="revolute">
    	<parent link="base_link"/>
    	<child link="left_front_link"/>
    	<origin xyz="0 0 0" rpy="0 0 0"/>
    	<axis xyz="0 0 1"/>
    	<limit lower="-3.1416" upper="3.1416" effort="10" velocity="3"/>
  	</joint>
	
 	<link name="base_link">
		<visual>
		    <origin xyz="0 0 0.1" rpy="0 0 0"/>
			<geometry>
				<box size="0.32 0.26 0.085"/>
			</geometry>
			<material name="Cyan1">
	       		<color rgba="0 0.9 0.9 1.0"/>
	     	</material>
		</visual>	
	</link>
    
</robot>