<?xml version="1.0" encoding="UTF-8"?>
<robot name="pi_robot">
	<!-- * * * Joint Definitions * * * -->

  <!-- * * * LEFT FRONT LEG Definitions * * * -->
	<link name="left_v_front_link">
		<visual>
			<origin xyz="0.025 0 0" rpy="0 0 0" />
			<geometry>
				<box size="0.03 0.015 0.045" />
			</geometry>
			<material name="Red1" />
		</visual>
    <collision>
			<origin xyz="0.025 0 0" rpy="0 0 0" />
			<geometry>
				<box size="0.03 0.015 0.045" />
			</geometry>
    </collision>
	</link>
  <link name="left_h_front_link">
		<visual>
			<origin xyz="0.025 0 0" rpy="0 0 0" />
			<geometry>
				<box size="0.03 0.045 0.015" />
			</geometry>
			<material name="Blue1" />
		</visual>
    <collision>
			<origin xyz="0.025 0 0" rpy="0 0 0" />
			<geometry>
				<box size="0.03 0.045 0.015" />
			</geometry>
    </collision>
	</link>
  <link name="left_front_leg_link">
		<visual>
			<origin xyz="0 0 -0.025" rpy="0 0 0" />
			<geometry>
				<box size="0.02 0.01 0.075" />
			</geometry>
			<material name="Green1" />
		</visual>
    <collision>
			<origin xyz="0 0 -0.025" rpy="0 0 0" />
			<geometry>
				<box size="0.02 0.01 0.075" />
			</geometry>
    </collision>
	</link>
  <joint name="left_front_joint" type="revolute">
		<parent link="base_link" />
		<child link="left_v_front_link" />
		<origin xyz="0.045 0.045 0" rpy="0 0 0" />
		<axis xyz="0 0 1" />
		<limit lower="-0.4" upper="2.5" effort="10" velocity="3" />
	</joint>
  <joint name="left_h_front_joint" type="fixed">
		<parent link="left_v_front_link" />
		<child link="left_h_front_link" />
		<origin xyz="0.02 0 0" rpy="0 0 0" />
	</joint>
  <joint name="left_front_leg_joint" type="revolute">
		<parent link="left_h_front_link" />
		<child  link="left_front_leg_link" />
		<origin xyz="0.04 0 0" rpy="0 0 0" />
		<axis xyz="0 1 0" />
		<limit lower="-0.6" upper="0.7" effort="10" velocity="3" />
	</joint>

  <!-- * * * RIGHT FRONT LEG Definitions * * * -->
	<link name="right_v_front_link">
		<visual>
			<origin xyz="0.025 0 0" rpy="0 0 0" />
			<geometry>
				<box size="0.03 0.015 0.045" />
         <!-- <mesh filename="meshes/servo_joint.stl"/> -->
			</geometry>
			<material name="Red1" />
		</visual>
    <collision>
			<origin xyz="0.025 0 0" rpy="0 0 0" />
			<geometry>
				<box size="0.03 0.015 0.045" />
         <!-- <mesh filename="meshes/servo_joint.stl"/> -->
			</geometry>
    </collision>
	</link>
  <link name="right_h_front_link">
		<visual>
			<origin xyz="0.025 0 0" rpy="0 0 0" />
			<geometry>
				<box size="0.03 0.045 0.015" />
			</geometry>
			<material name="Blue1" />
		</visual>
    <collision>
      <origin xyz="0.025 0 0" rpy="0 0 0" />
			<geometry>
				<box size="0.03 0.045 0.015" />
			</geometry>
    </collision>
	</link>
  <link name="right_front_leg_link">
		<visual>
			<origin xyz="0 0 -0.025" rpy="0 0 0" />
			<geometry>
				<box size="0.02 0.01 0.075" />
			</geometry>
			<material name="Green1" />
		</visual>
    <collision>
      <origin xyz="0 0 -0.025" rpy="0 0 0" />
			<geometry>
				<box size="0.02 0.01 0.075" />
			</geometry>
    </collision>
	</link>
  <joint name="right_front_joint" type="revolute">
		<parent link="base_link" />
		<child link="right_v_front_link" />
		<origin xyz="0.045 -0.045 0" rpy="0 0 0" />
		<axis xyz="0 0 1" />
		<limit lower="-2.5" upper="0.4" effort="10" velocity="3" />
	</joint>
  <joint name="right_h_front_joint" type="fixed">
		<parent link="right_v_front_link" />
		<child  link="right_h_front_link" />
		<origin xyz="0.02 0 0" rpy="0 0 0" />
	</joint>
  <joint name="right_front_leg_joint" type="revolute">
		<parent link="right_h_front_link" />
		<child link="right_front_leg_link" />
		<origin xyz="0.04 0 0" rpy="0 0 0" />
		<axis xyz="0 1 0" />
		<limit lower="-0.6" upper="0.7" effort="10" velocity="3" />
	</joint>

  <!-- * * * LEFT BACK LEG Definitions * * * -->
	<link name="left_v_back_link">
		<visual>
			<origin xyz="-0.025 0 0" rpy="0 0 0" />
			<geometry>
				<box size="0.03 0.015 0.045" />
			</geometry>
			<material name="Red1" />
		</visual>
    <collision>
      <origin xyz="-0.025 0 0" rpy="0 0 0" />
			<geometry>
				<box size="0.03 0.015 0.045" />
			</geometry>
    </collision>
	</link>
  <link name="left_h_back_link">
		<visual>
			<origin xyz="-0.025 0 0" rpy="0 0 0" />
			<geometry>
				<box size="0.03 0.045 0.015" />
			</geometry>
			<material name="Blue1" />
		</visual>
    <collision>
      <origin xyz="-0.025 0 0" rpy="0 0 0" />
			<geometry>
				<box size="0.03 0.045 0.015" />
			</geometry>
    </collision>
	</link>
  <link name="left_back_leg_link">
		<visual>
			<origin xyz="0 0 -0.025" rpy="0 0 0" />
			<geometry>
				<box size="0.02 0.01 0.075" />
			</geometry>
			<material name="Green1" />
		</visual>
    <collision>
      <origin xyz="0 0 -0.025" rpy="0 0 0" />
			<geometry>
				<box size="0.02 0.01 0.075" />
			</geometry>
    </collision>
	</link>
  <joint name="left_back_joint" type="revolute">
		<parent link="base_link" />
		<child link="left_v_back_link" />
		<origin xyz="-0.045 0.045 0" rpy="0 0 0" />
		<axis xyz="0 0 1" />
		<limit lower="-2.5" upper="0.4" effort="10" velocity="3" />
	</joint>
  <joint name="left_h_back_joint" type="fixed">
		<parent link="left_v_back_link" />
		<child  link="left_h_back_link" />
		<origin xyz="-0.02 0 0" rpy="0 0 0" />
	</joint>
  <joint name="left_back_leg_joint" type="revolute">
		<parent link="left_h_back_link" />
		<child link="left_back_leg_link" />
		<origin xyz="-0.04 0 0" rpy="0 0 0" />
		<axis xyz="0 1 0" />
		<limit lower="-0.6" upper="0.7" effort="10" velocity="3" />
	</joint>

  <!-- * * * RIGHT BACK LEG Definitions * * * -->
	<link name="right_v_back_link">
		<visual>
			<origin xyz="-0.025 0 0" rpy="0 0 0" />
			<geometry>
				<box size="0.03 0.015 0.045" />
			</geometry>
			<material name="Red1" />
		</visual>
    <collision>
      <origin xyz="-0.025 0 0" rpy="0 0 0" />
			<geometry>
				<box size="0.03 0.015 0.045" />
			</geometry>
    </collision>
	</link>
  <link name="right_h_back_link">
		<visual>
			<origin xyz="-0.025 0 0" rpy="0 0 0" />
			<geometry>
				<box size="0.03 0.045 0.015" />
			</geometry>
			<material name="Blue1" />
		</visual>
    <collision>
      <origin xyz="-0.025 0 0" rpy="0 0 0" />
			<geometry>
				<box size="0.03 0.045 0.015" />
			</geometry>
    </collision>
	</link>
  <link name="right_back_leg_link">
		<visual>
			<origin xyz="0 0 -0.025" rpy="0 0 0" />
			<geometry>
				<box size="0.02 0.01 0.075" />
			</geometry>
			<material name="Green1" />
		</visual>
    <collision>
      <origin xyz="0 0 -0.025" rpy="0 0 0" />
			<geometry>
				<box size="0.02 0.01 0.075" />
			</geometry>
    </collision>
	</link>
  <joint name="right_back_joint" type="revolute">
		<parent link="base_link" />
		<child  link="right_v_back_link" />
		<origin xyz="-0.045 -0.045 0" rpy="0 0 0" />
		<axis xyz="0 0 1" />
		<limit lower="-0.4" upper="2.5" effort="10" velocity="3" />
	</joint>
  <joint name="right_h_back_joint" type="fixed">
		<parent link="right_v_back_link" />
		<child  link="right_h_back_link" />
		<origin xyz="-0.02 0 0" rpy="0 0 0" />
	</joint>
  <joint name="right_back_leg_joint" type="revolute">
		<parent link="right_h_back_link" />
		<child link="right_back_leg_link" />
		<origin xyz="-0.04 0 0" rpy="0 0 0" />
		<axis xyz="0 1 0" />
		<limit lower="-0.6" upper="0.7" effort="10" velocity="3" />
	</joint>
	
	<!-- * * * BASE LINK Definitions * * * -->
	<link name="base_link">
		<visual>
			<origin xyz="0 0 0" rpy="0 0 0" />
			<geometry>
				<box size="0.125 0.125 0.035" />
			</geometry>
			<material name="Cyan1" />
		</visual>
    <collision>
      <origin xyz="0 0 0" rpy="0 0 0" />
			<geometry>
				<box size="0.125 0.125 0.035" />
			</geometry>
    </collision>
	</link>
	<!-- * * * Colors Definitions * * * -->
	<material name="Red1">
		<color rgba="0.9 0 0 1.0" />
	</material>
	<material name="Cyan1">
		<color rgba="0 0.9 0.9 1.0" />
	</material>
	<material name="Black1">
		<color rgba="0.2 0.2 0.2 1.0" />
	</material>
	<material name="Green1">
		<color rgba="0 1 0 1.0" />
	</material>
	<material name="Blue1">
		<color rgba="0 0 0.9 1.0" />
	</material>
	<material name="Grey1">
		<color rgba="0.9 0.9 0.9 1.0" />
	</material>
</robot>